[2024-11-12T00:30:13.027+0000] {local_task_job_runner.py:120} INFO - ::group::Pre task execution logs
[2024-11-12T00:30:13.116+0000] {taskinstance.py:2076} INFO - Dependencies all met for dep_context=non-requeueable deps ti=<TaskInstance: BuildELT_dbt.dbt_run_moving_average manual__2024-11-12T00:30:11.812197+00:00 [queued]>
[2024-11-12T00:30:13.135+0000] {taskinstance.py:2076} INFO - Dependencies all met for dep_context=requeueable deps ti=<TaskInstance: BuildELT_dbt.dbt_run_moving_average manual__2024-11-12T00:30:11.812197+00:00 [queued]>
[2024-11-12T00:30:13.136+0000] {taskinstance.py:2306} INFO - Starting attempt 1 of 1
[2024-11-12T00:30:13.224+0000] {taskinstance.py:2330} INFO - Executing <Task(BashOperator): dbt_run_moving_average> on 2024-11-12 00:30:11.812197+00:00
[2024-11-12T00:30:13.233+0000] {standard_task_runner.py:90} INFO - Running: ['***', 'tasks', 'run', 'BuildELT_dbt', 'dbt_run_moving_average', 'manual__2024-11-12T00:30:11.812197+00:00', '--job-id', '246', '--raw', '--subdir', 'DAGS_FOLDER/build_elt_with_dbt.py', '--cfg-path', '/tmp/tmpk2d8cmi8']
[2024-11-12T00:30:13.238+0000] {standard_task_runner.py:91} INFO - Job 246: Subtask dbt_run_moving_average
[2024-11-12T00:30:13.239+0000] {logging_mixin.py:188} WARNING - /home/***/.local/lib/python3.12/site-packages/***/task/task_runner/standard_task_runner.py:61 DeprecationWarning: This process (pid=377) is multi-threaded, use of fork() may lead to deadlocks in the child.
[2024-11-12T00:30:13.241+0000] {standard_task_runner.py:63} INFO - Started process 386 to run task
[2024-11-12T00:30:13.305+0000] {task_command.py:426} INFO - Running <TaskInstance: BuildELT_dbt.dbt_run_moving_average manual__2024-11-12T00:30:11.812197+00:00 [running]> on host df2dacc12cb8
[2024-11-12T00:30:13.387+0000] {taskinstance.py:2648} INFO - Exporting env vars: AIRFLOW_CTX_DAG_OWNER='***' AIRFLOW_CTX_DAG_ID='BuildELT_dbt' AIRFLOW_CTX_TASK_ID='dbt_run_moving_average' AIRFLOW_CTX_EXECUTION_DATE='2024-11-12T00:30:11.812197+00:00' AIRFLOW_CTX_TRY_NUMBER='1' AIRFLOW_CTX_DAG_RUN_ID='manual__2024-11-12T00:30:11.812197+00:00'
[2024-11-12T00:30:13.387+0000] {taskinstance.py:430} INFO - ::endgroup::
[2024-11-12T00:30:13.406+0000] {subprocess.py:63} INFO - Tmp dir root location: /tmp
[2024-11-12T00:30:13.407+0000] {subprocess.py:75} INFO - Running command: ['/usr/bin/bash', '-c', '/home/***/.local/bin/dbt run --models moving_average --profiles-dir /opt/***/dbt --project-dir /opt/***/dbt']
[2024-11-12T00:30:13.414+0000] {subprocess.py:86} INFO - Output:
[2024-11-12T00:30:15.860+0000] {subprocess.py:93} INFO - [0m00:30:15  Running with dbt=1.8.8
[2024-11-12T00:30:17.097+0000] {subprocess.py:93} INFO - [0m00:30:17  Registered adapter: snowflake=1.8.4
[2024-11-12T00:30:17.110+0000] {subprocess.py:93} INFO - [0m00:30:17  Encountered an error:
[2024-11-12T00:30:17.111+0000] {subprocess.py:93} INFO - Compilation Error
[2024-11-12T00:30:17.111+0000] {subprocess.py:93} INFO -   dbt found more than one package with the name "dbt" included in this project. Package names must be unique in a project. Please rename one of these packages.
[2024-11-12T00:30:18.004+0000] {subprocess.py:97} INFO - Command exited with return code 2
[2024-11-12T00:30:18.004+0000] {taskinstance.py:441} INFO - ::group::Post task execution logs
[2024-11-12T00:30:18.016+0000] {taskinstance.py:2905} ERROR - Task failed with exception
Traceback (most recent call last):
  File "/home/airflow/.local/lib/python3.12/site-packages/airflow/models/taskinstance.py", line 465, in _execute_task
    result = _execute_callable(context=context, **execute_callable_kwargs)
             ^^^^^^^^^^^^^^^^^^^^^^^^^^^^^^^^^^^^^^^^^^^^^^^^^^^^^^^^^^^^^
  File "/home/airflow/.local/lib/python3.12/site-packages/airflow/models/taskinstance.py", line 432, in _execute_callable
    return execute_callable(context=context, **execute_callable_kwargs)
           ^^^^^^^^^^^^^^^^^^^^^^^^^^^^^^^^^^^^^^^^^^^^^^^^^^^^^^^^^^^^
  File "/home/airflow/.local/lib/python3.12/site-packages/airflow/models/baseoperator.py", line 400, in wrapper
    return func(self, *args, **kwargs)
           ^^^^^^^^^^^^^^^^^^^^^^^^^^^
  File "/home/airflow/.local/lib/python3.12/site-packages/airflow/operators/bash.py", line 243, in execute
    raise AirflowException(
airflow.exceptions.AirflowException: Bash command failed. The command returned a non-zero exit code 2.
[2024-11-12T00:30:18.021+0000] {taskinstance.py:1206} INFO - Marking task as FAILED. dag_id=BuildELT_dbt, task_id=dbt_run_moving_average, run_id=manual__2024-11-12T00:30:11.812197+00:00, execution_date=20241112T003011, start_date=20241112T003013, end_date=20241112T003018
[2024-11-12T00:30:18.035+0000] {standard_task_runner.py:110} ERROR - Failed to execute job 246 for task dbt_run_moving_average (Bash command failed. The command returned a non-zero exit code 2.; 386)
[2024-11-12T00:30:18.073+0000] {local_task_job_runner.py:240} INFO - Task exited with return code 1
[2024-11-12T00:30:18.097+0000] {taskinstance.py:3498} INFO - 0 downstream tasks scheduled from follow-on schedule check
[2024-11-12T00:30:18.101+0000] {local_task_job_runner.py:222} INFO - ::endgroup::
