[2024-11-11T03:50:01.220+0000] {local_task_job_runner.py:120} INFO - ::group::Pre task execution logs
[2024-11-11T03:50:01.258+0000] {taskinstance.py:2076} INFO - Dependencies all met for dep_context=non-requeueable deps ti=<TaskInstance: two_stocks_DAG.predict_stock scheduled__2024-11-10T03:50:00+00:00 [queued]>
[2024-11-11T03:50:01.269+0000] {taskinstance.py:2076} INFO - Dependencies all met for dep_context=requeueable deps ti=<TaskInstance: two_stocks_DAG.predict_stock scheduled__2024-11-10T03:50:00+00:00 [queued]>
[2024-11-11T03:50:01.270+0000] {taskinstance.py:2306} INFO - Starting attempt 1 of 3
[2024-11-11T03:50:01.282+0000] {taskinstance.py:2330} INFO - Executing <Task(_PythonDecoratedOperator): predict_stock> on 2024-11-10 03:50:00+00:00
[2024-11-11T03:50:01.289+0000] {logging_mixin.py:188} WARNING - /home/***/.local/lib/python3.12/site-packages/***/task/task_runner/standard_task_runner.py:61 DeprecationWarning: This process (pid=838) is multi-threaded, use of fork() may lead to deadlocks in the child.
[2024-11-11T03:50:01.291+0000] {standard_task_runner.py:63} INFO - Started process 855 to run task
[2024-11-11T03:50:01.290+0000] {standard_task_runner.py:90} INFO - Running: ['***', 'tasks', 'run', 'two_stocks_DAG', 'predict_stock', 'scheduled__2024-11-10T03:50:00+00:00', '--job-id', '93', '--raw', '--subdir', 'DAGS_FOLDER/two_stocks.py', '--cfg-path', '/tmp/tmpsx4qmmtv']
[2024-11-11T03:50:01.292+0000] {standard_task_runner.py:91} INFO - Job 93: Subtask predict_stock
[2024-11-11T03:50:01.351+0000] {task_command.py:426} INFO - Running <TaskInstance: two_stocks_DAG.predict_stock scheduled__2024-11-10T03:50:00+00:00 [running]> on host e77131eeb98c
[2024-11-11T03:50:01.446+0000] {taskinstance.py:2648} INFO - Exporting env vars: AIRFLOW_CTX_DAG_OWNER='***' AIRFLOW_CTX_DAG_ID='two_stocks_DAG' AIRFLOW_CTX_TASK_ID='predict_stock' AIRFLOW_CTX_EXECUTION_DATE='2024-11-10T03:50:00+00:00' AIRFLOW_CTX_TRY_NUMBER='1' AIRFLOW_CTX_DAG_RUN_ID='scheduled__2024-11-10T03:50:00+00:00'
[2024-11-11T03:50:01.447+0000] {taskinstance.py:430} INFO - ::endgroup::
[2024-11-11T03:50:01.459+0000] {base.py:84} INFO - Using connection ID 'snowflake_conn' for task execution.
[2024-11-11T03:50:01.460+0000] {connection.py:399} INFO - Snowflake Connector for Python Version: 3.10.0, Python Version: 3.12.3, Platform: Linux-5.15.153.1-microsoft-standard-WSL2-x86_64-with-glibc2.36
[2024-11-11T03:50:01.461+0000] {connection.py:1239} INFO - This connection is in OCSP Fail Open Mode. TLS Certificates would be checked for validity and revocation status. Any other Certificate Revocation related exceptions or OCSP Responder failures would be disregarded in favor of connectivity.
[2024-11-11T03:50:01.815+0000] {taskinstance.py:441} INFO - ::group::Post task execution logs
[2024-11-11T03:50:01.816+0000] {taskinstance.py:2905} ERROR - Task failed with exception
Traceback (most recent call last):
  File "/home/airflow/.local/lib/python3.12/site-packages/airflow/models/taskinstance.py", line 465, in _execute_task
    result = _execute_callable(context=context, **execute_callable_kwargs)
             ^^^^^^^^^^^^^^^^^^^^^^^^^^^^^^^^^^^^^^^^^^^^^^^^^^^^^^^^^^^^^
  File "/home/airflow/.local/lib/python3.12/site-packages/airflow/models/taskinstance.py", line 432, in _execute_callable
    return execute_callable(context=context, **execute_callable_kwargs)
           ^^^^^^^^^^^^^^^^^^^^^^^^^^^^^^^^^^^^^^^^^^^^^^^^^^^^^^^^^^^^
  File "/home/airflow/.local/lib/python3.12/site-packages/airflow/models/baseoperator.py", line 400, in wrapper
    return func(self, *args, **kwargs)
           ^^^^^^^^^^^^^^^^^^^^^^^^^^^
  File "/home/airflow/.local/lib/python3.12/site-packages/airflow/decorators/base.py", line 265, in execute
    return_value = super().execute(context)
                   ^^^^^^^^^^^^^^^^^^^^^^^^
  File "/home/airflow/.local/lib/python3.12/site-packages/airflow/models/baseoperator.py", line 400, in wrapper
    return func(self, *args, **kwargs)
           ^^^^^^^^^^^^^^^^^^^^^^^^^^^
  File "/home/airflow/.local/lib/python3.12/site-packages/airflow/operators/python.py", line 235, in execute
    return_value = self.execute_callable()
                   ^^^^^^^^^^^^^^^^^^^^^^^
  File "/home/airflow/.local/lib/python3.12/site-packages/airflow/operators/python.py", line 252, in execute_callable
    return self.python_callable(*self.op_args, **self.op_kwargs)
           ^^^^^^^^^^^^^^^^^^^^^^^^^^^^^^^^^^^^^^^^^^^^^^^^^^^^^
  File "/opt/airflow/dags/two_stocks.py", line 118, in predict_stock
    cur = return_snowflake_conn()
          ^^^^^^^^^^^^^^^^^^^^^^^
  File "/opt/airflow/dags/two_stocks.py", line 13, in return_snowflake_conn
    conn = hook.get_conn()
           ^^^^^^^^^^^^^^^
  File "/home/airflow/.local/lib/python3.12/site-packages/airflow/providers/snowflake/hooks/snowflake.py", line 287, in get_conn
    conn = connector.connect(**conn_config)
           ^^^^^^^^^^^^^^^^^^^^^^^^^^^^^^^^
  File "/home/airflow/.local/lib/python3.12/site-packages/snowflake/connector/__init__.py", line 55, in Connect
    return SnowflakeConnection(**kwargs)
           ^^^^^^^^^^^^^^^^^^^^^^^^^^^^^
  File "/home/airflow/.local/lib/python3.12/site-packages/snowflake/connector/connection.py", line 442, in __init__
    self.connect(**kwargs)
  File "/home/airflow/.local/lib/python3.12/site-packages/snowflake/connector/connection.py", line 745, in connect
    self.__open_connection()
  File "/home/airflow/.local/lib/python3.12/site-packages/snowflake/connector/connection.py", line 1073, in __open_connection
    self.authenticate_with_retry(self.auth_class)
  File "/home/airflow/.local/lib/python3.12/site-packages/snowflake/connector/connection.py", line 1345, in authenticate_with_retry
    self._authenticate(auth_instance)
  File "/home/airflow/.local/lib/python3.12/site-packages/snowflake/connector/connection.py", line 1373, in _authenticate
    auth.authenticate(
  File "/home/airflow/.local/lib/python3.12/site-packages/snowflake/connector/auth/_auth.py", line 250, in authenticate
    ret = self._rest._post_request(
          ^^^^^^^^^^^^^^^^^^^^^^^^^
  File "/home/airflow/.local/lib/python3.12/site-packages/snowflake/connector/network.py", line 734, in _post_request
    ret = self.fetch(
          ^^^^^^^^^^^
  File "/home/airflow/.local/lib/python3.12/site-packages/snowflake/connector/network.py", line 843, in fetch
    ret = self._request_exec_wrapper(
          ^^^^^^^^^^^^^^^^^^^^^^^^^^^
  File "/home/airflow/.local/lib/python3.12/site-packages/snowflake/connector/network.py", line 979, in _request_exec_wrapper
    raise e
  File "/home/airflow/.local/lib/python3.12/site-packages/snowflake/connector/network.py", line 884, in _request_exec_wrapper
    return_object = self._request_exec(
                    ^^^^^^^^^^^^^^^^^^^
  File "/home/airflow/.local/lib/python3.12/site-packages/snowflake/connector/network.py", line 1193, in _request_exec
    raise err
  File "/home/airflow/.local/lib/python3.12/site-packages/snowflake/connector/network.py", line 1135, in _request_exec
    raise_failed_request_error(
  File "/home/airflow/.local/lib/python3.12/site-packages/snowflake/connector/network.py", line 238, in raise_failed_request_error
    Error.errorhandler_wrapper(
  File "/home/airflow/.local/lib/python3.12/site-packages/snowflake/connector/errors.py", line 290, in errorhandler_wrapper
    handed_over = Error.hand_to_other_handler(
                  ^^^^^^^^^^^^^^^^^^^^^^^^^^^^
  File "/home/airflow/.local/lib/python3.12/site-packages/snowflake/connector/errors.py", line 348, in hand_to_other_handler
    connection.errorhandler(connection, cursor, error_class, error_value)
  File "/home/airflow/.local/lib/python3.12/site-packages/snowflake/connector/errors.py", line 221, in default_errorhandler
    raise error_class(
snowflake.connector.errors.InterfaceError: 250003 (08001): None: 404 Not Found: post https://azb69635.snowflakecomputing.com:443/session/v1/login-request?request_id=c762caf3-6853-4e07-86f3-c9a6413099b9&databaseName=DEV&schemaName=&warehouse=COMPUTE_WH&roleName=&request_guid=c1f06e09-16d5-4ab6-a04d-82a2ecdb7bbb
[2024-11-11T03:50:01.830+0000] {taskinstance.py:1206} INFO - Marking task as UP_FOR_RETRY. dag_id=two_stocks_DAG, task_id=predict_stock, run_id=scheduled__2024-11-10T03:50:00+00:00, execution_date=20241110T035000, start_date=20241111T035001, end_date=20241111T035001
[2024-11-11T03:50:01.844+0000] {standard_task_runner.py:110} ERROR - Failed to execute job 93 for task predict_stock (250003 (08001): None: 404 Not Found: post https://azb69635.snowflakecomputing.com:443/session/v1/login-request?request_id=c762caf3-6853-4e07-86f3-c9a6413099b9&databaseName=DEV&schemaName=&warehouse=COMPUTE_WH&roleName=&request_guid=c1f06e09-16d5-4ab6-a04d-82a2ecdb7bbb; 855)
[2024-11-11T03:50:01.866+0000] {local_task_job_runner.py:240} INFO - Task exited with return code 1
[2024-11-11T03:50:01.877+0000] {local_task_job_runner.py:222} INFO - ::endgroup::
[2024-11-11T03:56:16.676+0000] {local_task_job_runner.py:120} INFO - ::group::Pre task execution logs
[2024-11-11T03:56:16.737+0000] {taskinstance.py:2076} INFO - Dependencies all met for dep_context=non-requeueable deps ti=<TaskInstance: two_stocks_DAG.predict_stock scheduled__2024-11-10T03:50:00+00:00 [queued]>
[2024-11-11T03:56:16.752+0000] {taskinstance.py:2076} INFO - Dependencies all met for dep_context=requeueable deps ti=<TaskInstance: two_stocks_DAG.predict_stock scheduled__2024-11-10T03:50:00+00:00 [queued]>
[2024-11-11T03:56:16.753+0000] {taskinstance.py:2306} INFO - Starting attempt 1 of 3
[2024-11-11T03:56:16.775+0000] {taskinstance.py:2330} INFO - Executing <Task(_PythonDecoratedOperator): predict_stock> on 2024-11-10 03:50:00+00:00
[2024-11-11T03:56:16.791+0000] {logging_mixin.py:188} WARNING - /home/***/.local/lib/python3.12/site-packages/***/task/task_runner/standard_task_runner.py:61 DeprecationWarning: This process (pid=1040) is multi-threaded, use of fork() may lead to deadlocks in the child.
[2024-11-11T03:56:16.795+0000] {standard_task_runner.py:63} INFO - Started process 1066 to run task
[2024-11-11T03:56:16.798+0000] {standard_task_runner.py:90} INFO - Running: ['***', 'tasks', 'run', 'two_stocks_DAG', 'predict_stock', 'scheduled__2024-11-10T03:50:00+00:00', '--job-id', '106', '--raw', '--subdir', 'DAGS_FOLDER/two_stocks.py', '--cfg-path', '/tmp/tmpb_8z287c']
[2024-11-11T03:56:16.803+0000] {standard_task_runner.py:91} INFO - Job 106: Subtask predict_stock
[2024-11-11T03:56:16.884+0000] {task_command.py:426} INFO - Running <TaskInstance: two_stocks_DAG.predict_stock scheduled__2024-11-10T03:50:00+00:00 [running]> on host e77131eeb98c
[2024-11-11T03:56:17.075+0000] {taskinstance.py:2648} INFO - Exporting env vars: AIRFLOW_CTX_DAG_OWNER='***' AIRFLOW_CTX_DAG_ID='two_stocks_DAG' AIRFLOW_CTX_TASK_ID='predict_stock' AIRFLOW_CTX_EXECUTION_DATE='2024-11-10T03:50:00+00:00' AIRFLOW_CTX_TRY_NUMBER='1' AIRFLOW_CTX_DAG_RUN_ID='scheduled__2024-11-10T03:50:00+00:00'
[2024-11-11T03:56:17.078+0000] {taskinstance.py:430} INFO - ::endgroup::
[2024-11-11T03:56:17.101+0000] {base.py:84} INFO - Using connection ID 'snowflake_conn' for task execution.
[2024-11-11T03:56:17.104+0000] {connection.py:399} INFO - Snowflake Connector for Python Version: 3.10.0, Python Version: 3.12.3, Platform: Linux-5.15.153.1-microsoft-standard-WSL2-x86_64-with-glibc2.36
[2024-11-11T03:56:17.106+0000] {connection.py:1239} INFO - This connection is in OCSP Fail Open Mode. TLS Certificates would be checked for validity and revocation status. Any other Certificate Revocation related exceptions or OCSP Responder failures would be disregarded in favor of connectivity.
[2024-11-11T03:56:17.556+0000] {taskinstance.py:441} INFO - ::group::Post task execution logs
[2024-11-11T03:56:17.557+0000] {taskinstance.py:2905} ERROR - Task failed with exception
Traceback (most recent call last):
  File "/home/airflow/.local/lib/python3.12/site-packages/airflow/models/taskinstance.py", line 465, in _execute_task
    result = _execute_callable(context=context, **execute_callable_kwargs)
             ^^^^^^^^^^^^^^^^^^^^^^^^^^^^^^^^^^^^^^^^^^^^^^^^^^^^^^^^^^^^^
  File "/home/airflow/.local/lib/python3.12/site-packages/airflow/models/taskinstance.py", line 432, in _execute_callable
    return execute_callable(context=context, **execute_callable_kwargs)
           ^^^^^^^^^^^^^^^^^^^^^^^^^^^^^^^^^^^^^^^^^^^^^^^^^^^^^^^^^^^^
  File "/home/airflow/.local/lib/python3.12/site-packages/airflow/models/baseoperator.py", line 400, in wrapper
    return func(self, *args, **kwargs)
           ^^^^^^^^^^^^^^^^^^^^^^^^^^^
  File "/home/airflow/.local/lib/python3.12/site-packages/airflow/decorators/base.py", line 265, in execute
    return_value = super().execute(context)
                   ^^^^^^^^^^^^^^^^^^^^^^^^
  File "/home/airflow/.local/lib/python3.12/site-packages/airflow/models/baseoperator.py", line 400, in wrapper
    return func(self, *args, **kwargs)
           ^^^^^^^^^^^^^^^^^^^^^^^^^^^
  File "/home/airflow/.local/lib/python3.12/site-packages/airflow/operators/python.py", line 235, in execute
    return_value = self.execute_callable()
                   ^^^^^^^^^^^^^^^^^^^^^^^
  File "/home/airflow/.local/lib/python3.12/site-packages/airflow/operators/python.py", line 252, in execute_callable
    return self.python_callable(*self.op_args, **self.op_kwargs)
           ^^^^^^^^^^^^^^^^^^^^^^^^^^^^^^^^^^^^^^^^^^^^^^^^^^^^^
  File "/opt/airflow/dags/two_stocks.py", line 118, in predict_stock
    cur = return_snowflake_conn()
          ^^^^^^^^^^^^^^^^^^^^^^^
  File "/opt/airflow/dags/two_stocks.py", line 13, in return_snowflake_conn
    conn = hook.get_conn()
           ^^^^^^^^^^^^^^^
  File "/home/airflow/.local/lib/python3.12/site-packages/airflow/providers/snowflake/hooks/snowflake.py", line 287, in get_conn
    conn = connector.connect(**conn_config)
           ^^^^^^^^^^^^^^^^^^^^^^^^^^^^^^^^
  File "/home/airflow/.local/lib/python3.12/site-packages/snowflake/connector/__init__.py", line 55, in Connect
    return SnowflakeConnection(**kwargs)
           ^^^^^^^^^^^^^^^^^^^^^^^^^^^^^
  File "/home/airflow/.local/lib/python3.12/site-packages/snowflake/connector/connection.py", line 442, in __init__
    self.connect(**kwargs)
  File "/home/airflow/.local/lib/python3.12/site-packages/snowflake/connector/connection.py", line 745, in connect
    self.__open_connection()
  File "/home/airflow/.local/lib/python3.12/site-packages/snowflake/connector/connection.py", line 1073, in __open_connection
    self.authenticate_with_retry(self.auth_class)
  File "/home/airflow/.local/lib/python3.12/site-packages/snowflake/connector/connection.py", line 1345, in authenticate_with_retry
    self._authenticate(auth_instance)
  File "/home/airflow/.local/lib/python3.12/site-packages/snowflake/connector/connection.py", line 1373, in _authenticate
    auth.authenticate(
  File "/home/airflow/.local/lib/python3.12/site-packages/snowflake/connector/auth/_auth.py", line 250, in authenticate
    ret = self._rest._post_request(
          ^^^^^^^^^^^^^^^^^^^^^^^^^
  File "/home/airflow/.local/lib/python3.12/site-packages/snowflake/connector/network.py", line 734, in _post_request
    ret = self.fetch(
          ^^^^^^^^^^^
  File "/home/airflow/.local/lib/python3.12/site-packages/snowflake/connector/network.py", line 843, in fetch
    ret = self._request_exec_wrapper(
          ^^^^^^^^^^^^^^^^^^^^^^^^^^^
  File "/home/airflow/.local/lib/python3.12/site-packages/snowflake/connector/network.py", line 979, in _request_exec_wrapper
    raise e
  File "/home/airflow/.local/lib/python3.12/site-packages/snowflake/connector/network.py", line 884, in _request_exec_wrapper
    return_object = self._request_exec(
                    ^^^^^^^^^^^^^^^^^^^
  File "/home/airflow/.local/lib/python3.12/site-packages/snowflake/connector/network.py", line 1193, in _request_exec
    raise err
  File "/home/airflow/.local/lib/python3.12/site-packages/snowflake/connector/network.py", line 1135, in _request_exec
    raise_failed_request_error(
  File "/home/airflow/.local/lib/python3.12/site-packages/snowflake/connector/network.py", line 238, in raise_failed_request_error
    Error.errorhandler_wrapper(
  File "/home/airflow/.local/lib/python3.12/site-packages/snowflake/connector/errors.py", line 290, in errorhandler_wrapper
    handed_over = Error.hand_to_other_handler(
                  ^^^^^^^^^^^^^^^^^^^^^^^^^^^^
  File "/home/airflow/.local/lib/python3.12/site-packages/snowflake/connector/errors.py", line 348, in hand_to_other_handler
    connection.errorhandler(connection, cursor, error_class, error_value)
  File "/home/airflow/.local/lib/python3.12/site-packages/snowflake/connector/errors.py", line 221, in default_errorhandler
    raise error_class(
snowflake.connector.errors.InterfaceError: 250003 (08001): None: 404 Not Found: post https://azb69635.snowflakecomputing.com:443/session/v1/login-request?request_id=96eb53be-5353-46ac-b295-fb48d96d9877&databaseName=DEV&schemaName=&warehouse=COMPUTE_WH&roleName=&request_guid=f3893d9e-dce5-4391-b5e4-a4e9c2077842
[2024-11-11T03:56:17.572+0000] {taskinstance.py:1206} INFO - Marking task as UP_FOR_RETRY. dag_id=two_stocks_DAG, task_id=predict_stock, run_id=scheduled__2024-11-10T03:50:00+00:00, execution_date=20241110T035000, start_date=20241111T035616, end_date=20241111T035617
[2024-11-11T03:56:17.590+0000] {standard_task_runner.py:110} ERROR - Failed to execute job 106 for task predict_stock (250003 (08001): None: 404 Not Found: post https://azb69635.snowflakecomputing.com:443/session/v1/login-request?request_id=96eb53be-5353-46ac-b295-fb48d96d9877&databaseName=DEV&schemaName=&warehouse=COMPUTE_WH&roleName=&request_guid=f3893d9e-dce5-4391-b5e4-a4e9c2077842; 1066)
[2024-11-11T03:56:17.624+0000] {local_task_job_runner.py:240} INFO - Task exited with return code 1
[2024-11-11T03:56:17.657+0000] {taskinstance.py:3498} INFO - 0 downstream tasks scheduled from follow-on schedule check
[2024-11-11T03:56:17.684+0000] {local_task_job_runner.py:222} INFO - ::endgroup::
[2024-11-11T21:07:51.912+0000] {local_task_job_runner.py:120} INFO - ::group::Pre task execution logs
[2024-11-11T21:07:51.974+0000] {taskinstance.py:2076} INFO - Dependencies all met for dep_context=non-requeueable deps ti=<TaskInstance: two_stocks_DAG.predict_stock scheduled__2024-11-10T03:50:00+00:00 [queued]>
[2024-11-11T21:07:51.992+0000] {taskinstance.py:2076} INFO - Dependencies all met for dep_context=requeueable deps ti=<TaskInstance: two_stocks_DAG.predict_stock scheduled__2024-11-10T03:50:00+00:00 [queued]>
[2024-11-11T21:07:51.994+0000] {taskinstance.py:2306} INFO - Starting attempt 1 of 3
[2024-11-11T21:07:52.018+0000] {taskinstance.py:2330} INFO - Executing <Task(_PythonDecoratedOperator): predict_stock> on 2024-11-10 03:50:00+00:00
[2024-11-11T21:07:52.027+0000] {warnings.py:110} WARNING - /home/***/.local/lib/python3.12/site-packages/***/task/task_runner/standard_task_runner.py:61: DeprecationWarning: This process (pid=401) is multi-threaded, use of fork() may lead to deadlocks in the child.
  pid = os.fork()

[2024-11-11T21:07:52.030+0000] {standard_task_runner.py:63} INFO - Started process 409 to run task
[2024-11-11T21:07:52.030+0000] {standard_task_runner.py:90} INFO - Running: ['***', 'tasks', 'run', 'two_stocks_DAG', 'predict_stock', 'scheduled__2024-11-10T03:50:00+00:00', '--job-id', '173', '--raw', '--subdir', 'DAGS_FOLDER/two_stocks.py', '--cfg-path', '/tmp/tmpq0swp7q7']
[2024-11-11T21:07:52.033+0000] {standard_task_runner.py:91} INFO - Job 173: Subtask predict_stock
[2024-11-11T21:07:52.554+0000] {task_command.py:426} INFO - Running <TaskInstance: two_stocks_DAG.predict_stock scheduled__2024-11-10T03:50:00+00:00 [running]> on host 889c1536fdc4
[2024-11-11T21:07:55.762+0000] {taskinstance.py:2648} INFO - Exporting env vars: AIRFLOW_CTX_DAG_OWNER='***' AIRFLOW_CTX_DAG_ID='two_stocks_DAG' AIRFLOW_CTX_TASK_ID='predict_stock' AIRFLOW_CTX_EXECUTION_DATE='2024-11-10T03:50:00+00:00' AIRFLOW_CTX_TRY_NUMBER='1' AIRFLOW_CTX_DAG_RUN_ID='scheduled__2024-11-10T03:50:00+00:00'
[2024-11-11T21:07:55.764+0000] {taskinstance.py:430} INFO - ::endgroup::
[2024-11-11T21:07:55.780+0000] {base.py:84} INFO - Using connection ID 'snowflake_conn' for task execution.
[2024-11-11T21:07:55.782+0000] {connection.py:399} INFO - Snowflake Connector for Python Version: 3.10.0, Python Version: 3.12.3, Platform: Linux-5.15.153.1-microsoft-standard-WSL2-x86_64-with-glibc2.36
[2024-11-11T21:07:55.784+0000] {connection.py:1239} INFO - This connection is in OCSP Fail Open Mode. TLS Certificates would be checked for validity and revocation status. Any other Certificate Revocation related exceptions or OCSP Responder failures would be disregarded in favor of connectivity.
[2024-11-11T21:07:56.048+0000] {taskinstance.py:441} INFO - ::group::Post task execution logs
[2024-11-11T21:07:56.048+0000] {taskinstance.py:2905} ERROR - Task failed with exception
Traceback (most recent call last):
  File "/home/airflow/.local/lib/python3.12/site-packages/airflow/models/taskinstance.py", line 465, in _execute_task
    result = _execute_callable(context=context, **execute_callable_kwargs)
             ^^^^^^^^^^^^^^^^^^^^^^^^^^^^^^^^^^^^^^^^^^^^^^^^^^^^^^^^^^^^^
  File "/home/airflow/.local/lib/python3.12/site-packages/airflow/models/taskinstance.py", line 432, in _execute_callable
    return execute_callable(context=context, **execute_callable_kwargs)
           ^^^^^^^^^^^^^^^^^^^^^^^^^^^^^^^^^^^^^^^^^^^^^^^^^^^^^^^^^^^^
  File "/home/airflow/.local/lib/python3.12/site-packages/airflow/models/baseoperator.py", line 400, in wrapper
    return func(self, *args, **kwargs)
           ^^^^^^^^^^^^^^^^^^^^^^^^^^^
  File "/home/airflow/.local/lib/python3.12/site-packages/airflow/decorators/base.py", line 265, in execute
    return_value = super().execute(context)
                   ^^^^^^^^^^^^^^^^^^^^^^^^
  File "/home/airflow/.local/lib/python3.12/site-packages/airflow/models/baseoperator.py", line 400, in wrapper
    return func(self, *args, **kwargs)
           ^^^^^^^^^^^^^^^^^^^^^^^^^^^
  File "/home/airflow/.local/lib/python3.12/site-packages/airflow/operators/python.py", line 235, in execute
    return_value = self.execute_callable()
                   ^^^^^^^^^^^^^^^^^^^^^^^
  File "/home/airflow/.local/lib/python3.12/site-packages/airflow/operators/python.py", line 252, in execute_callable
    return self.python_callable(*self.op_args, **self.op_kwargs)
           ^^^^^^^^^^^^^^^^^^^^^^^^^^^^^^^^^^^^^^^^^^^^^^^^^^^^^
  File "/opt/airflow/dags/two_stocks.py", line 118, in predict_stock
    cur = return_snowflake_conn()
          ^^^^^^^^^^^^^^^^^^^^^^^
  File "/opt/airflow/dags/two_stocks.py", line 13, in return_snowflake_conn
    conn = hook.get_conn()
           ^^^^^^^^^^^^^^^
  File "/home/airflow/.local/lib/python3.12/site-packages/airflow/providers/snowflake/hooks/snowflake.py", line 287, in get_conn
    conn = connector.connect(**conn_config)
           ^^^^^^^^^^^^^^^^^^^^^^^^^^^^^^^^
  File "/home/airflow/.local/lib/python3.12/site-packages/snowflake/connector/__init__.py", line 55, in Connect
    return SnowflakeConnection(**kwargs)
           ^^^^^^^^^^^^^^^^^^^^^^^^^^^^^
  File "/home/airflow/.local/lib/python3.12/site-packages/snowflake/connector/connection.py", line 442, in __init__
    self.connect(**kwargs)
  File "/home/airflow/.local/lib/python3.12/site-packages/snowflake/connector/connection.py", line 745, in connect
    self.__open_connection()
  File "/home/airflow/.local/lib/python3.12/site-packages/snowflake/connector/connection.py", line 1073, in __open_connection
    self.authenticate_with_retry(self.auth_class)
  File "/home/airflow/.local/lib/python3.12/site-packages/snowflake/connector/connection.py", line 1345, in authenticate_with_retry
    self._authenticate(auth_instance)
  File "/home/airflow/.local/lib/python3.12/site-packages/snowflake/connector/connection.py", line 1373, in _authenticate
    auth.authenticate(
  File "/home/airflow/.local/lib/python3.12/site-packages/snowflake/connector/auth/_auth.py", line 250, in authenticate
    ret = self._rest._post_request(
          ^^^^^^^^^^^^^^^^^^^^^^^^^
  File "/home/airflow/.local/lib/python3.12/site-packages/snowflake/connector/network.py", line 734, in _post_request
    ret = self.fetch(
          ^^^^^^^^^^^
  File "/home/airflow/.local/lib/python3.12/site-packages/snowflake/connector/network.py", line 843, in fetch
    ret = self._request_exec_wrapper(
          ^^^^^^^^^^^^^^^^^^^^^^^^^^^
  File "/home/airflow/.local/lib/python3.12/site-packages/snowflake/connector/network.py", line 979, in _request_exec_wrapper
    raise e
  File "/home/airflow/.local/lib/python3.12/site-packages/snowflake/connector/network.py", line 884, in _request_exec_wrapper
    return_object = self._request_exec(
                    ^^^^^^^^^^^^^^^^^^^
  File "/home/airflow/.local/lib/python3.12/site-packages/snowflake/connector/network.py", line 1193, in _request_exec
    raise err
  File "/home/airflow/.local/lib/python3.12/site-packages/snowflake/connector/network.py", line 1135, in _request_exec
    raise_failed_request_error(
  File "/home/airflow/.local/lib/python3.12/site-packages/snowflake/connector/network.py", line 238, in raise_failed_request_error
    Error.errorhandler_wrapper(
  File "/home/airflow/.local/lib/python3.12/site-packages/snowflake/connector/errors.py", line 290, in errorhandler_wrapper
    handed_over = Error.hand_to_other_handler(
                  ^^^^^^^^^^^^^^^^^^^^^^^^^^^^
  File "/home/airflow/.local/lib/python3.12/site-packages/snowflake/connector/errors.py", line 348, in hand_to_other_handler
    connection.errorhandler(connection, cursor, error_class, error_value)
  File "/home/airflow/.local/lib/python3.12/site-packages/snowflake/connector/errors.py", line 221, in default_errorhandler
    raise error_class(
snowflake.connector.errors.InterfaceError: 250003 (08001): None: 404 Not Found: post https://azb69635.snowflakecomputing.com:443/session/v1/login-request?request_id=47a8c0ab-afe2-4b07-b485-71fd1370acb3&databaseName=DEV&schemaName=&warehouse=COMPUTE_WH&roleName=&request_guid=f104902c-b3c5-4fc9-913c-e96e46223164
[2024-11-11T21:07:56.065+0000] {taskinstance.py:1206} INFO - Marking task as UP_FOR_RETRY. dag_id=two_stocks_DAG, task_id=predict_stock, run_id=scheduled__2024-11-10T03:50:00+00:00, execution_date=20241110T035000, start_date=20241111T210751, end_date=20241111T210756
[2024-11-11T21:07:56.081+0000] {standard_task_runner.py:110} ERROR - Failed to execute job 173 for task predict_stock (250003 (08001): None: 404 Not Found: post https://azb69635.snowflakecomputing.com:443/session/v1/login-request?request_id=47a8c0ab-afe2-4b07-b485-71fd1370acb3&databaseName=DEV&schemaName=&warehouse=COMPUTE_WH&roleName=&request_guid=f104902c-b3c5-4fc9-913c-e96e46223164; 409)
[2024-11-11T21:07:56.128+0000] {local_task_job_runner.py:240} INFO - Task exited with return code 1
[2024-11-11T21:07:56.159+0000] {taskinstance.py:3498} INFO - 0 downstream tasks scheduled from follow-on schedule check
[2024-11-11T21:07:56.161+0000] {local_task_job_runner.py:222} INFO - ::endgroup::
[2024-11-11T21:10:22.472+0000] {local_task_job_runner.py:120} INFO - ::group::Pre task execution logs
[2024-11-11T21:10:22.496+0000] {taskinstance.py:2076} INFO - Dependencies all met for dep_context=non-requeueable deps ti=<TaskInstance: two_stocks_DAG.predict_stock scheduled__2024-11-10T03:50:00+00:00 [queued]>
[2024-11-11T21:10:22.504+0000] {taskinstance.py:2076} INFO - Dependencies all met for dep_context=requeueable deps ti=<TaskInstance: two_stocks_DAG.predict_stock scheduled__2024-11-10T03:50:00+00:00 [queued]>
[2024-11-11T21:10:22.504+0000] {taskinstance.py:2306} INFO - Starting attempt 1 of 3
[2024-11-11T21:10:22.521+0000] {taskinstance.py:2330} INFO - Executing <Task(_PythonDecoratedOperator): predict_stock> on 2024-11-10 03:50:00+00:00
[2024-11-11T21:10:22.528+0000] {warnings.py:110} WARNING - /home/***/.local/lib/python3.12/site-packages/***/task/task_runner/standard_task_runner.py:61: DeprecationWarning: This process (pid=477) is multi-threaded, use of fork() may lead to deadlocks in the child.
  pid = os.fork()

[2024-11-11T21:10:22.529+0000] {standard_task_runner.py:63} INFO - Started process 489 to run task
[2024-11-11T21:10:22.529+0000] {standard_task_runner.py:90} INFO - Running: ['***', 'tasks', 'run', 'two_stocks_DAG', 'predict_stock', 'scheduled__2024-11-10T03:50:00+00:00', '--job-id', '190', '--raw', '--subdir', 'DAGS_FOLDER/two_stocks.py', '--cfg-path', '/tmp/tmp1c7q_kbb']
[2024-11-11T21:10:22.530+0000] {standard_task_runner.py:91} INFO - Job 190: Subtask predict_stock
[2024-11-11T21:10:22.584+0000] {task_command.py:426} INFO - Running <TaskInstance: two_stocks_DAG.predict_stock scheduled__2024-11-10T03:50:00+00:00 [running]> on host 889c1536fdc4
[2024-11-11T21:10:22.672+0000] {taskinstance.py:2648} INFO - Exporting env vars: AIRFLOW_CTX_DAG_OWNER='***' AIRFLOW_CTX_DAG_ID='two_stocks_DAG' AIRFLOW_CTX_TASK_ID='predict_stock' AIRFLOW_CTX_EXECUTION_DATE='2024-11-10T03:50:00+00:00' AIRFLOW_CTX_TRY_NUMBER='1' AIRFLOW_CTX_DAG_RUN_ID='scheduled__2024-11-10T03:50:00+00:00'
[2024-11-11T21:10:22.674+0000] {taskinstance.py:430} INFO - ::endgroup::
[2024-11-11T21:10:22.684+0000] {base.py:84} INFO - Using connection ID 'snowflake_conn' for task execution.
[2024-11-11T21:10:22.685+0000] {connection.py:399} INFO - Snowflake Connector for Python Version: 3.10.0, Python Version: 3.12.3, Platform: Linux-5.15.153.1-microsoft-standard-WSL2-x86_64-with-glibc2.36
[2024-11-11T21:10:22.687+0000] {connection.py:1239} INFO - This connection is in OCSP Fail Open Mode. TLS Certificates would be checked for validity and revocation status. Any other Certificate Revocation related exceptions or OCSP Responder failures would be disregarded in favor of connectivity.
[2024-11-11T21:10:23.467+0000] {logging_mixin.py:188} INFO - 002141 (42601): 01b84eb6-0004-26ad-0000-000258f77885: Uncaught exception of type 'STATEMENT_ERROR' on line 2 at position 8 : SQL compilation error:
Unknown user-defined function STOCK_DATA_DB.ANALYTICS.PREDICT_LMT_STOCK_PRICE!FORECAST
[2024-11-11T21:10:23.467+0000] {taskinstance.py:441} INFO - ::group::Post task execution logs
[2024-11-11T21:10:23.468+0000] {taskinstance.py:2905} ERROR - Task failed with exception
Traceback (most recent call last):
  File "/home/airflow/.local/lib/python3.12/site-packages/airflow/models/taskinstance.py", line 465, in _execute_task
    result = _execute_callable(context=context, **execute_callable_kwargs)
             ^^^^^^^^^^^^^^^^^^^^^^^^^^^^^^^^^^^^^^^^^^^^^^^^^^^^^^^^^^^^^
  File "/home/airflow/.local/lib/python3.12/site-packages/airflow/models/taskinstance.py", line 432, in _execute_callable
    return execute_callable(context=context, **execute_callable_kwargs)
           ^^^^^^^^^^^^^^^^^^^^^^^^^^^^^^^^^^^^^^^^^^^^^^^^^^^^^^^^^^^^
  File "/home/airflow/.local/lib/python3.12/site-packages/airflow/models/baseoperator.py", line 400, in wrapper
    return func(self, *args, **kwargs)
           ^^^^^^^^^^^^^^^^^^^^^^^^^^^
  File "/home/airflow/.local/lib/python3.12/site-packages/airflow/decorators/base.py", line 265, in execute
    return_value = super().execute(context)
                   ^^^^^^^^^^^^^^^^^^^^^^^^
  File "/home/airflow/.local/lib/python3.12/site-packages/airflow/models/baseoperator.py", line 400, in wrapper
    return func(self, *args, **kwargs)
           ^^^^^^^^^^^^^^^^^^^^^^^^^^^
  File "/home/airflow/.local/lib/python3.12/site-packages/airflow/operators/python.py", line 235, in execute
    return_value = self.execute_callable()
                   ^^^^^^^^^^^^^^^^^^^^^^^
  File "/home/airflow/.local/lib/python3.12/site-packages/airflow/operators/python.py", line 252, in execute_callable
    return self.python_callable(*self.op_args, **self.op_kwargs)
           ^^^^^^^^^^^^^^^^^^^^^^^^^^^^^^^^^^^^^^^^^^^^^^^^^^^^^
  File "/opt/airflow/dags/two_stocks.py", line 142, in predict_stock
    cur.execute(make_prediction_sql)
  File "/home/airflow/.local/lib/python3.12/site-packages/snowflake/connector/cursor.py", line 1080, in execute
    Error.errorhandler_wrapper(self.connection, self, error_class, errvalue)
  File "/home/airflow/.local/lib/python3.12/site-packages/snowflake/connector/errors.py", line 290, in errorhandler_wrapper
    handed_over = Error.hand_to_other_handler(
                  ^^^^^^^^^^^^^^^^^^^^^^^^^^^^
  File "/home/airflow/.local/lib/python3.12/site-packages/snowflake/connector/errors.py", line 345, in hand_to_other_handler
    cursor.errorhandler(connection, cursor, error_class, error_value)
  File "/home/airflow/.local/lib/python3.12/site-packages/snowflake/connector/errors.py", line 221, in default_errorhandler
    raise error_class(
snowflake.connector.errors.ProgrammingError: 002141 (42601): 01b84eb6-0004-26ad-0000-000258f77885: Uncaught exception of type 'STATEMENT_ERROR' on line 2 at position 8 : SQL compilation error:
Unknown user-defined function STOCK_DATA_DB.ANALYTICS.PREDICT_LMT_STOCK_PRICE!FORECAST
[2024-11-11T21:10:23.477+0000] {taskinstance.py:1206} INFO - Marking task as UP_FOR_RETRY. dag_id=two_stocks_DAG, task_id=predict_stock, run_id=scheduled__2024-11-10T03:50:00+00:00, execution_date=20241110T035000, start_date=20241111T211022, end_date=20241111T211023
[2024-11-11T21:10:23.490+0000] {standard_task_runner.py:110} ERROR - Failed to execute job 190 for task predict_stock (002141 (42601): 01b84eb6-0004-26ad-0000-000258f77885: Uncaught exception of type 'STATEMENT_ERROR' on line 2 at position 8 : SQL compilation error:
Unknown user-defined function STOCK_DATA_DB.ANALYTICS.PREDICT_LMT_STOCK_PRICE!FORECAST; 489)
[2024-11-11T21:10:23.506+0000] {local_task_job_runner.py:240} INFO - Task exited with return code 1
[2024-11-11T21:10:23.517+0000] {local_task_job_runner.py:222} INFO - ::endgroup::
