[2024-11-11T23:16:52.706+0000] {local_task_job_runner.py:120} INFO - ::group::Pre task execution logs
[2024-11-11T23:16:52.746+0000] {taskinstance.py:2076} INFO - Dependencies all met for dep_context=non-requeueable deps ti=<TaskInstance: BuildELT_dbt.dbt_run_moving_average manual__2024-11-11T23:16:51.936693+00:00 [queued]>
[2024-11-11T23:16:52.758+0000] {taskinstance.py:2076} INFO - Dependencies all met for dep_context=requeueable deps ti=<TaskInstance: BuildELT_dbt.dbt_run_moving_average manual__2024-11-11T23:16:51.936693+00:00 [queued]>
[2024-11-11T23:16:52.759+0000] {taskinstance.py:2306} INFO - Starting attempt 1 of 1
[2024-11-11T23:16:52.775+0000] {taskinstance.py:2330} INFO - Executing <Task(BashOperator): dbt_run_moving_average> on 2024-11-11 23:16:51.936693+00:00
[2024-11-11T23:16:52.781+0000] {standard_task_runner.py:90} INFO - Running: ['***', 'tasks', 'run', 'BuildELT_dbt', 'dbt_run_moving_average', 'manual__2024-11-11T23:16:51.936693+00:00', '--job-id', '230', '--raw', '--subdir', 'DAGS_FOLDER/build_elt_with_dbt.py', '--cfg-path', '/tmp/tmp7ylclux_']
[2024-11-11T23:16:52.784+0000] {standard_task_runner.py:91} INFO - Job 230: Subtask dbt_run_moving_average
[2024-11-11T23:16:52.785+0000] {logging_mixin.py:188} WARNING - /home/***/.local/lib/python3.12/site-packages/***/task/task_runner/standard_task_runner.py:61 DeprecationWarning: This process (pid=756) is multi-threaded, use of fork() may lead to deadlocks in the child.
[2024-11-11T23:16:52.786+0000] {standard_task_runner.py:63} INFO - Started process 757 to run task
[2024-11-11T23:16:52.838+0000] {task_command.py:426} INFO - Running <TaskInstance: BuildELT_dbt.dbt_run_moving_average manual__2024-11-11T23:16:51.936693+00:00 [running]> on host 5f57ce551deb
[2024-11-11T23:16:52.966+0000] {taskinstance.py:2648} INFO - Exporting env vars: AIRFLOW_CTX_DAG_OWNER='***' AIRFLOW_CTX_DAG_ID='BuildELT_dbt' AIRFLOW_CTX_TASK_ID='dbt_run_moving_average' AIRFLOW_CTX_EXECUTION_DATE='2024-11-11T23:16:51.936693+00:00' AIRFLOW_CTX_TRY_NUMBER='1' AIRFLOW_CTX_DAG_RUN_ID='manual__2024-11-11T23:16:51.936693+00:00'
[2024-11-11T23:16:52.967+0000] {taskinstance.py:430} INFO - ::endgroup::
[2024-11-11T23:16:53.000+0000] {subprocess.py:63} INFO - Tmp dir root location: /tmp
[2024-11-11T23:16:53.001+0000] {subprocess.py:75} INFO - Running command: ['/usr/bin/bash', '-c', '/home/***/.local/bin/dbt run --models moving_average --profiles-dir /opt/***/build_test2 --project-dir /opt/***/build_test2']
[2024-11-11T23:16:53.010+0000] {subprocess.py:86} INFO - Output:
[2024-11-11T23:16:55.027+0000] {subprocess.py:93} INFO - Usage: dbt run [OPTIONS]
[2024-11-11T23:16:55.028+0000] {subprocess.py:93} INFO - Try 'dbt run -h' for help.
[2024-11-11T23:16:55.028+0000] {subprocess.py:93} INFO - 
[2024-11-11T23:16:55.029+0000] {subprocess.py:93} INFO - Error: Invalid value for '--profiles-dir': Path '/opt/***/build_test2' does not exist.
[2024-11-11T23:16:55.217+0000] {subprocess.py:97} INFO - Command exited with return code 2
[2024-11-11T23:16:55.219+0000] {taskinstance.py:441} INFO - ::group::Post task execution logs
[2024-11-11T23:16:55.229+0000] {taskinstance.py:2905} ERROR - Task failed with exception
Traceback (most recent call last):
  File "/home/airflow/.local/lib/python3.12/site-packages/airflow/models/taskinstance.py", line 465, in _execute_task
    result = _execute_callable(context=context, **execute_callable_kwargs)
             ^^^^^^^^^^^^^^^^^^^^^^^^^^^^^^^^^^^^^^^^^^^^^^^^^^^^^^^^^^^^^
  File "/home/airflow/.local/lib/python3.12/site-packages/airflow/models/taskinstance.py", line 432, in _execute_callable
    return execute_callable(context=context, **execute_callable_kwargs)
           ^^^^^^^^^^^^^^^^^^^^^^^^^^^^^^^^^^^^^^^^^^^^^^^^^^^^^^^^^^^^
  File "/home/airflow/.local/lib/python3.12/site-packages/airflow/models/baseoperator.py", line 400, in wrapper
    return func(self, *args, **kwargs)
           ^^^^^^^^^^^^^^^^^^^^^^^^^^^
  File "/home/airflow/.local/lib/python3.12/site-packages/airflow/operators/bash.py", line 243, in execute
    raise AirflowException(
airflow.exceptions.AirflowException: Bash command failed. The command returned a non-zero exit code 2.
[2024-11-11T23:16:55.233+0000] {taskinstance.py:1206} INFO - Marking task as FAILED. dag_id=BuildELT_dbt, task_id=dbt_run_moving_average, run_id=manual__2024-11-11T23:16:51.936693+00:00, execution_date=20241111T231651, start_date=20241111T231652, end_date=20241111T231655
[2024-11-11T23:16:55.245+0000] {standard_task_runner.py:110} ERROR - Failed to execute job 230 for task dbt_run_moving_average (Bash command failed. The command returned a non-zero exit code 2.; 757)
[2024-11-11T23:16:55.289+0000] {local_task_job_runner.py:240} INFO - Task exited with return code 1
[2024-11-11T23:16:55.313+0000] {taskinstance.py:3498} INFO - 0 downstream tasks scheduled from follow-on schedule check
[2024-11-11T23:16:55.317+0000] {local_task_job_runner.py:222} INFO - ::endgroup::
